Workbook

Sheet Data
A1: Duration (in seconds) | B1: ID | C1: Duration (in minutes) | D1: Install (in minutes) | E1: Q1.2_First Click | F1: Q1.2_Last Click | G1: Q1.2_Page Submit | H1: Q1.2_Click Count | I1: Library version | J1: Class standing | K1: Major | L1: Gender | M1: Documentation Timing | N1: Q3.1_First Click | O1: Q3.1_Last Click | P1: Q3.1_Page Submit | Q1: Q3.1_Click Count | R1: Policy 1 Timing | S1: Q3.3_First Click | T1: Q3.3_Last Click | U1: Q3.3_Page Submit | V1: Q3.3_Click Count | W1: Policy 1 Parses | X1: Policy 1 Correct | Y1: Policy 1 Method | Z1: Policy 1 ASQ | AA1: Q3.6_1 | AB1: Q3.6_2 | AC1: Q3.6_3 | AD1: Policy 2 Timing | AE1: Q3.7_First Click | AF1: Q3.7_Last Click | AG1: Q3.7_Page Submit | AH1: Q3.7_Click Count | AI1: Policy 2 Parses | AJ1: Policy 2 Correct | AK1: Policy 2 Method | AL1: Policy 2 ASQ | AM1: Q3.10_1 | AN1: Q3.10_2 | AO1: Q3.10_3 | AP1: Policy 3 Timing | AQ1: Q3.11_First Click | AR1: Q3.11_Last Click | AS1: Q3.11_Page Submit | AT1: Q3.11_Click Count | AU1: Policy 3 Parses | AV1: Policy 3 Correct | AW1: Policy 3 Method | AX1: Policy 3 ASQ | AY1: Q3.14_1 | AZ1: Q3.14_2 | BA1: Q3.14_3 | BB1: Policy 4 Timing | BC1: Q3.15_First Click | BD1: Q3.15_Last Click | BE1: Q3.15_Page Submit | BF1: Q3.15_Click Count | BG1: Policy 4 Parses | BH1: Policy 4 Correct | BI1: Policy 4 Method | BJ1: Policy 4 ASQ | BK1: Q3.18_1 | BL1: Q3.18_2 | BM1: Q3.18_3 | BN1: Policy 5 Timing | BO1: Q3.19_First Click | BP1: Q3.19_Last Click | BQ1: Q3.19_Page Submit | BR1: Q3.19_Click Count | BS1: Policy 5 Parses | BT1: Policy 5 Correct | BU1: Policy 5 Method | BV1: Policy 5 ASQ | BW1: Q3.22_1 | BX1: Q3.22_2 | BY1: Q3.22_3 | BZ1: Q4.2_1 | CA1: Q4.2_2 | CB1: Q4.2_3 | CC1: Q4.2_4 | CD1: Q4.2_5 | CE1: Q4.2_6 | CF1: Q4.2_7 | CG1: Q4.2_8 | CH1: Q4.2_9 | CI1: Q4.2_10 | CJ1: Total Correct | CK1: SUS | CL1: Liked best | CM1: Disliked most | CN1: Other feedback
A2: 3983 | B2: R1 | C2: =A2/60 -> 66.383333 | D2: =(G2-E2)/60 -> 24.771767 | E2: 11.273 | F2: 1493.875 | G2: 1497.579 | H2: 31 | I2: 0.1.3 | J2: Senior | K2: Computer Science | L2: Male | M2: =(P2-N2)/60 -> 0.62171667 | N2: 1.805 | O2: 38.192 | P2: 39.108 | Q2: 15 | R2: =(U2-S2)/60 -> 2.4311167 | S2: 1.188 | T2: 111.945 | U2: 147.055 | V2: 23 | W2: TRUE | X2: TRUE | Y2: Manual | Z2: =AVERAGE(AA2:AC2) -> 7 | AA2: 7 | AB2: 7 | AC2: 7 | AD2: =(AG2-AE2)/60 -> 6.5135167 | AE2: 1.154 | AF2: 390.246 | AG2: 391.965 | AH2: 21 | AI2: TRUE | AJ2: TRUE | AK2: Manual | AL2: =AVERAGE(AM2:AO2) -> 6.3333333 | AM2: 7 | AN2: 5 | AO2: 7 | AP2: =(AS2-AQ2)/60 -> 13.0778 | AQ2: 2.195 | AR2: 749.074 | AS2: 786.863 | AT2: 86 | AU2: TRUE | AV2: TRUE | AW2: Manual | AX2: =AVERAGE(AY2:BA2) -> 3 | AY2: 1 | AZ2: 1 | BA2: 7 | BB2: =(BE2-BC2)/60 -> 7.31535 | BC2: 0.915 | BD2: 326.669 | BE2: 439.836 | BF2: 55 | BG2: TRUE | BH2: TRUE | BI2: Manual | BJ2: =AVERAGE(BK2:BM2) -> 2.3333333 | BK2: 1 | BL2: 5 | BM2: 1 | BN2: =(BQ2-BO2)/60 -> 2.3081833 | BO2: 1.088 | BP2: 112.115 | BQ2: 139.579 | BR2: 43 | BS2: TRUE | BT2: TRUE | BU2: Manual | BV2: =AVERAGE(BW2:BY2) -> 3 | BW2: 1 | BX2: 7 | BY2: 1 | BZ2: Strongly disagree | CA2: Disagree | CB2: Neither Agree nor Disagree | CC2: Agree | CD2: Agree | CE2: Disagree | CF2: Agree | CG2: Disagree | CH2: Strongly disagree | CI2: Disagree | CJ2: =COUNTIF(X2,TRUE)+COUNTIF(AJ2,TRUE)+COUNTIF(AV2,TRUE)+COUNTIF(BH2,TRUE)+COUNTIF(BT2,TRUE) -> 5 | CK2: =(VLOOKUP(BZ2,References!$A$1:$C$6,2)+VLOOKUP(CA2,References!$A$1:$C$6,3)+VLOOKUP(CB2,References!$A$1:$C$6,2)+VLOOKUP(CC2,References!$A$1:$C$6,3)+VLOOKUP(CD2,References!$A$1:$C$6,2)+VLOOKUP(CE2,References!$A$1:$C$6,3)+VLOOKUP(CF2,References!$A$1:$C$6,2)+VLOOKUP(CG2,References!$A$1:$C$6,3)+VLOOKUP(CH2,References!$A$1:$C$6,2)+VLOOKUP(CI2,References!$A$1:$C$6,3))*2.5 -> 50 | CL2: the system is not too complex, but there are a few things I couldn't figure out (multiple main rules, minimum requirements for letters/numbers, etc.) | CM2: i didn't try the library but the system itself was a bit hard to understand when trying to add more complex rules. i wish i had some examples for those but it would've probably undermined the questions in the trial. | CN2: no
A3: 51835 | B3: R2 | C3: =A3/60 -> 863.91667 | D3: =(G3-E3)/60 -> 9.8195833 | E3: 59.741 | F3: 645.218 | G3: 648.916 | H3: 4 | I3: 0.1.3 | J3: Junior | K3: Computer Engineering | L3: Male | M3: =(P3-N3)/60 -> 0.46908333 | N3: 0 | O3: 0 | P3: 28.145 | Q3: 0 | R3: =(U3-S3)/60 -> 13.74025 | S3: 76.069 | T3: 883.829 | U3: 900.484 | V3: 2 | W3: TRUE | X3: TRUE | Y3: Manual | Z3: =AVERAGE(AA3:AC3) -> 4.6666667 | AA3: 7 | AB3: 5 | AC3: 2 | AD3: =(AG3-AE3)/60 -> 9.8462667 | AE3: 9.11 | AF3: 592.321 | AG3: 599.886 | AH3: 43 | AI3: TRUE | AJ3: TRUE | AK3: Manual | AL3: =AVERAGE(AM3:AO3) -> 5 | AM3: 7 | AN3: 6 | AO3: 2 | AP3: =(AS3-AQ3)/60 -> 2.8189167 | AQ3: 3.433 | AR3: 154.461 | AS3: 172.568 | AT3: 5 | AU3: TRUE | AV3: TRUE | AW3: Manual | AX3: =AVERAGE(AY3:BA3) -> 5.6666667 | AY3: 7 | AZ3: 6 | BA3: 4 | BB3: =(BE3-BC3)/60 -> 6.2292167 | BC3: 65.242 | BD3: 435.905 | BE3: 438.995 | BF3: 22 | BG3: TRUE | BH3: TRUE | BI3: Manual | BJ3: =AVERAGE(BK3:BM3) -> 5.6666667 | BK3: 7 | BL3: 6 | BM3: 4 | BN3: =(BQ3-BO3)/60 -> 8.7915167 | BO3: 9.096 | BP3: 475.816 | BQ3: 536.587 | BR3: 18 | BS3: TRUE | BT3: TRUE | BU3: Manual | BV3: =AVERAGE(BW3:BY3) -> 6 | BW3: 7 | BX3: 7 | BY3: 4 | BZ3: Neither Agree nor Disagree | CA3: Agree | CB3: Agree | CC3: Strongly disagree | CD3: Disagree | CE3: Neither Agree nor Disagree | CF3: Disagree | CG3: Agree | CH3: Strongly Agree | CI3: Strongly disagree | CJ3: =COUNTIF(X3,TRUE)+COUNTIF(AJ3,TRUE)+COUNTIF(AV3,TRUE)+COUNTIF(BH3,TRUE)+COUNTIF(BT3,TRUE) -> 5 | CK3: =(VLOOKUP(BZ3,References!$A$1:$C$6,2)+VLOOKUP(CA3,References!$A$1:$C$6,3)+VLOOKUP(CB3,References!$A$1:$C$6,2)+VLOOKUP(CC3,References!$A$1:$C$6,3)+VLOOKUP(CD3,References!$A$1:$C$6,2)+VLOOKUP(CE3,References!$A$1:$C$6,3)+VLOOKUP(CF3,References!$A$1:$C$6,2)+VLOOKUP(CG3,References!$A$1:$C$6,3)+VLOOKUP(CH3,References!$A$1:$C$6,2)+VLOOKUP(CI3,References!$A$1:$C$6,3))*2.5 -> 50 | CL3: I enjoyed that the language felt innovative, and a true attempt at resolving a perceived problem. I highly commend the effort and thought that was put into this project. A positive for people who are not as skilled in computer science is that this system is more like filling in a form than actually writing a set of restrictions, which makes it easier to conceptualize. | CM3: the nested array system feels a little clumsy, and I believe that there are better solutions than ones that require so much attention to detail when it comes to aligning brackets. | CN3: Good Luck!!!
A4: 1653 | B4: R3 | C4: =A4/60 -> 27.55 | D4: =(G4-E4)/60 -> 0.47025 | E4: 1.338 | F4: 24.05 | G4: 29.553 | H4: 10 | I4: 0.1.9 | J4: Senior | K4: Computer Science | L4: Female | M4: =(P4-N4)/60 -> 0.3433 | N4: 0 | O4: 0 | P4: 20.598 | Q4: 0 | R4: =(U4-S4)/60 -> 0.703 | S4: 35.187 | T4: 49.467 | U4: 77.367 | V4: 3 | W4: TRUE | X4: TRUE | Y4: Manual | Z4: =AVERAGE(AA4:AC4) -> 7 | AA4: 7 | AB4: 7 | AC4: 7 | AD4: =(AG4-AE4)/60 -> 1.2097 | AE4: 2.99 | AF4: 60.685 | AG4: 75.572 | AH4: 7 | AI4: TRUE | AJ4: TRUE | AK4: Manual | AL4: =AVERAGE(AM4:AO4) -> 7 | AM4: 7 | AN4: 7 | AO4: 7 | AP4: =(AS4-AQ4)/60 -> 8.60985 | AQ4: 10.593 | AR4: 10.699 | AS4: 527.184 | AT4: 2 | AU4: TRUE | AV4: TRUE | AW4: Generated | AX4: =AVERAGE(AY4:BA4) -> 3.3333333 | AY4: 3 | AZ4: 2 | BA4: 5 | BB4: =(BE4-BC4)/60 -> 0.03705 | BC4: 124.65 | BD4: 124.65 | BE4: 126.873 | BF4: 1 | BG4: TRUE | BH4: TRUE | BI4: Generated | BJ4: =AVERAGE(BK4:BM4) -> 6 | BK4: 5 | BL4: 6 | BM4: 7 | BN4: =(BQ4-BO4)/60 -> 0.071233333 | BO4: 474.059 | BP4: 474.059 | BQ4: 478.333 | BR4: 1 | BS4: TRUE | BT4: TRUE | BU4: Generated | BV4: =AVERAGE(BW4:BY4) -> 2 | BW4: 1 | BX4: 1 | BY4: 4 | BZ4: Agree | CA4: Strongly Agree | CB4: Neither Agree nor Disagree | CC4: Disagree | CD4: Agree | CE4: Neither Agree nor Disagree | CF4: Disagree | CG4: Strongly Agree | CH4: Disagree | CI4: Disagree | CJ4: =COUNTIF(X4,TRUE)+COUNTIF(AJ4,TRUE)+COUNTIF(AV4,TRUE)+COUNTIF(BH4,TRUE)+COUNTIF(BT4,TRUE) -> 5 | CK4: =(VLOOKUP(BZ4,References!$A$1:$C$6,2)+VLOOKUP(CA4,References!$A$1:$C$6,3)+VLOOKUP(CB4,References!$A$1:$C$6,2)+VLOOKUP(CC4,References!$A$1:$C$6,3)+VLOOKUP(CD4,References!$A$1:$C$6,2)+VLOOKUP(CE4,References!$A$1:$C$6,3)+VLOOKUP(CF4,References!$A$1:$C$6,2)+VLOOKUP(CG4,References!$A$1:$C$6,3)+VLOOKUP(CH4,References!$A$1:$C$6,2)+VLOOKUP(CI4,References!$A$1:$C$6,3))*2.5 -> 60 | CL4: Making a simple password policy was very fast | CM4: I like verbosity, but this was a bit much. | CN4: I don't see why the alphabet character set can't be used by simple rules.
A5: 2570 | B5: R4 | C5: =A5/60 -> 42.833333 | D5: =(G5-E5)/60 -> 0.32041667 | E5: 362.633 | F5: 378.778 | G5: 381.858 | H5: 4 | I5: 0.1.9 | J5: MS student | K5: Computer Science | L5: Female | M5: =(P5-N5)/60 -> 0.62155 | N5: 19.521 | O5: 19.521 | P5: 56.814 | Q5: 1 | R5: =(U5-S5)/60 -> 0.65921667 | S5: 13.653 | T5: 50.864 | U5: 53.206 | V5: 14 | W5: TRUE | X5: TRUE | Y5: Manual | Z5: =AVERAGE(AA5:AC5) -> 7 | AA5: 7 | AB5: 7 | AC5: 7 | AD5: =(AG5-AE5)/60 -> 0.6671 | AE5: 21.708 | AF5: 58.195 | AG5: 61.734 | AH5: 8 | AI5: TRUE | AJ5: TRUE | AK5: Manual | AL5: =AVERAGE(AM5:AO5) -> 6.3333333 | AM5: 6 | AN5: 6 | AO5: 7 | AP5: =(AS5-AQ5)/60 -> 13.0483 | AQ5: 41.561 | AR5: 822.865 | AS5: 824.459 | AT5: 30 | AU5: TRUE | AV5: TRUE | AW5: Generated | AX5: =AVERAGE(AY5:BA5) -> 3.6666667 | AY5: 3 | AZ5: 3 | BA5: 5 | BB5: =(BE5-BC5)/60 -> 0.032966667 | BC5: 173.497 | BD5: 173.497 | BE5: 175.475 | BF5: 1 | BG5: TRUE | BH5: TRUE | BI5: Generated | BJ5: =AVERAGE(BK5:BM5) -> 6.3333333 | BK5: 6 | BL5: 6 | BM5: 7 | BN5: =(BQ5-BO5)/60 -> 7.8138833 | BO5: 194.354 | BP5: 660.53 | BQ5: 663.187 | BR5: 3 | BS5: TRUE | BT5: TRUE | BU5: Generated | BV5: =AVERAGE(BW5:BY5) -> 1.3333333 | BW5: 2 | BX5: 1 | BY5: 1 | BZ5: Agree | CA5: Disagree | CB5: Agree | CC5: Strongly disagree | CD5: Agree | CE5: Neither Agree nor Disagree | CF5: Agree | CG5: Disagree | CH5: Agree | CI5: Disagree | CJ5: =COUNTIF(X5,TRUE)+COUNTIF(AJ5,TRUE)+COUNTIF(AV5,TRUE)+COUNTIF(BH5,TRUE)+COUNTIF(BT5,TRUE) -> 5 | CK5: =(VLOOKUP(BZ5,References!$A$1:$C$6,2)+VLOOKUP(CA5,References!$A$1:$C$6,3)+VLOOKUP(CB5,References!$A$1:$C$6,2)+VLOOKUP(CC5,References!$A$1:$C$6,3)+VLOOKUP(CD5,References!$A$1:$C$6,2)+VLOOKUP(CE5,References!$A$1:$C$6,3)+VLOOKUP(CF5,References!$A$1:$C$6,2)+VLOOKUP(CG5,References!$A$1:$C$6,3)+VLOOKUP(CH5,References!$A$1:$C$6,2)+VLOOKUP(CI5,References!$A$1:$C$6,3))*2.5 -> 77.5 | CL5: Clear naming scheme | CM5: The documentation didn't make it clear if SimplePCP features also applied to PCP. For example, I guessed that the SimplePCP prohibited substrings feature was also compatible with PCP, but the documentation didn't say.
A6: 3215 | B6: R5 | C6: =A6/60 -> 53.583333 | D6: =(G6-E6)/60 -> 0.18496667 | E6: 103.363 | F6: 110.477 | G6: 114.461 | H6: 4 | I6: 0.1.9 | J6: Senior | K6: Computer Science | L6: Male | M6: =(P6-N6)/60 -> 0.10255 | N6: 14.946 | O6: 14.946 | P6: 21.099 | Q6: 1 | R6: =(U6-S6)/60 -> 0.05445 | S6: 120.291 | T6: 120.291 | U6: 123.558 | V6: 1 | W6: TRUE | X6: TRUE | Y6: Generated | Z6: =AVERAGE(AA6:AC6) -> 7 | AA6: 7 | AB6: 7 | AC6: 7 | AD6: =(AG6-AE6)/60 -> 0.035416667 | AE6: 157.71 | AF6: 157.71 | AG6: 159.835 | AH6: 1 | AI6: TRUE | AJ6: TRUE | AK6: Generated | AL6: =AVERAGE(AM6:AO6) -> 7 | AM6: 7 | AN6: 7 | AO6: 7 | AP6: =(AS6-AQ6)/60 -> 10.251283 | AQ6: 130.896 | AR6: 741.518 | AS6: 745.973 | AT6: 10 | AU6: TRUE | AV6: FALSE | AW6: Generated | AX6: =AVERAGE(AY6:BA6) -> 5.6666667 | AY6: 7 | AZ6: 4 | BA6: 6 | BB6: =(BE6-BC6)/60 -> 12.521117 | BC6: 202.657 | BD6: 951.9 | BE6: 953.924 | BF6: 13 | BG6: TRUE | BH6: TRUE | BI6: Generated | BJ6: =AVERAGE(BK6:BM6) -> 5.3333333 | BK6: 5 | BL6: 5 | BM6: 6 | BN6: =(BQ6-BO6)/60 -> 3.6462 | BO6: 451.002 | BP6: 667.808 | BQ6: 669.774 | BR6: 3 | BS6: TRUE | BT6: TRUE | BU6: Generated | BV6: =AVERAGE(BW6:BY6) -> 7 | BW6: 7 | BX6: 7 | BY6: 7 | BZ6: Agree | CA6: Disagree | CB6: Agree | CC6: Disagree | CD6: Agree | CE6: Disagree | CF6: Agree | CG6: Disagree | CH6: Agree | CI6: Strongly disagree | CJ6: =COUNTIF(X6,TRUE)+COUNTIF(AJ6,TRUE)+COUNTIF(AV6,TRUE)+COUNTIF(BH6,TRUE)+COUNTIF(BT6,TRUE) -> 4 | CK6: =(VLOOKUP(BZ6,References!$A$1:$C$6,2)+VLOOKUP(CA6,References!$A$1:$C$6,3)+VLOOKUP(CB6,References!$A$1:$C$6,2)+VLOOKUP(CC6,References!$A$1:$C$6,3)+VLOOKUP(CD6,References!$A$1:$C$6,2)+VLOOKUP(CE6,References!$A$1:$C$6,3)+VLOOKUP(CF6,References!$A$1:$C$6,2)+VLOOKUP(CG6,References!$A$1:$C$6,3)+VLOOKUP(CH6,References!$A$1:$C$6,2)+VLOOKUP(CI6,References!$A$1:$C$6,3))*2.5 -> 77.5 | CL6: I liked the power it gives the policy writer. | CM6: Character control felt a little confusing. | CN6: I think there could be better documentation for different character regulation scenarios, I had to trial and error a couple of the questions quite a few times to get it just right.
A7: 2216 | B7: R6 | C7: =A7/60 -> 36.933333 | D7: =(G7-E7)/60 -> 2.73025 | E7: 3.277 | F7: 166.203 | G7: 167.092 | H7: 15 | I7: 0.1.9 | J7: Senior | K7: Computer Science | L7: Male | M7: =(P7-N7)/60 -> 0.13543333 | N7: 22.394 | O7: 22.394 | P7: 30.52 | Q7: 1 | R7: =(U7-S7)/60 -> 0.0816 | S7: 446.156 | T7: 449.935 | U7: 451.052 | V7: 3 | W7: TRUE | X7: TRUE | Y7: Generated | Z7: =AVERAGE(AA7:AC7) -> 6.6666667 | AA7: 7 | AB7: 6 | AC7: 7 | AD7: =(AG7-AE7)/60 -> 1.5230333 | AE7: 173.607 | AF7: 263.857 | AG7: 264.989 | AH7: 7 | AI7: TRUE | AJ7: TRUE | AK7: Generated | AL7: =AVERAGE(AM7:AO7) -> 7 | AM7: 7 | AN7: 7 | AO7: 7 | AP7: =(AS7-AQ7)/60 -> 0.38436667 | AQ7: 366.265 | AR7: 387.093 | AS7: 389.327 | AT7: 3 | AU7: TRUE | AV7: TRUE | AW7: Generated | AX7: =AVERAGE(AY7:BA7) -> 7 | AY7: 7 | AZ7: 7 | BA7: 7 | BB7: =(BE7-BC7)/60 -> 0.055083333 | BC7: 222.243 | BD7: 223.366 | BE7: 225.548 | BF7: 2 | BG7: TRUE | BH7: TRUE | BI7: Generated | BJ7: =AVERAGE(BK7:BM7) -> 7 | BK7: 7 | BL7: 7 | BM7: 7 | BN7: =(BQ7-BO7)/60 -> 0.0423 | BO7: 388.997 | BP7: 388.997 | BQ7: 391.535 | BR7: 1 | BS7: TRUE | BT7: TRUE | BU7: Generated | BV7: =AVERAGE(BW7:BY7) -> 7 | BW7: 7 | BX7: 7 | BY7: 7 | BZ7: Strongly Agree | CA7: Disagree | CB7: Agree | CC7: Disagree | CD7: Agree | CE7: Disagree | CF7: Agree | CG7: Disagree | CH7: Strongly Agree | CI7: Disagree | CJ7: =COUNTIF(X7,TRUE)+COUNTIF(AJ7,TRUE)+COUNTIF(AV7,TRUE)+COUNTIF(BH7,TRUE)+COUNTIF(BT7,TRUE) -> 5 | CK7: =(VLOOKUP(BZ7,References!$A$1:$C$6,2)+VLOOKUP(CA7,References!$A$1:$C$6,3)+VLOOKUP(CB7,References!$A$1:$C$6,2)+VLOOKUP(CC7,References!$A$1:$C$6,3)+VLOOKUP(CD7,References!$A$1:$C$6,2)+VLOOKUP(CE7,References!$A$1:$C$6,3)+VLOOKUP(CF7,References!$A$1:$C$6,2)+VLOOKUP(CG7,References!$A$1:$C$6,3)+VLOOKUP(CH7,References!$A$1:$C$6,2)+VLOOKUP(CI7,References!$A$1:$C$6,3))*2.5 -> 65 | CL7: The documentation is very well laid out and easy to understand. I enjoy the ease of use of the program. It's easy to follow make configurations for complex password configurations. | CM7: I didn't quite understand why or when it's necessary to switch between "pcp = PCP()" and "pcp = SimplePCP()".
A8: 3388 | B8: R7 | C8: =A8/60 -> 56.466667 | D8: =(G8-E8)/60 -> 1.9872667 | E8: 34.599 | F8: 149.74 | G8: 153.835 | H8: 13 | I8: 0.1.9 | J8: Senior | K8: Computer Science | L8: Male | M8: =(P8-N8)/60 -> 0.064716667 | N8: 2.614 | O8: 5.264 | P8: 6.497 | Q8: 5 | R8: =(U8-S8)/60 -> 17.7125 | S8: 28.496 | T8: 1085.854 | U8: 1091.246 | V8: 4 | W8: TRUE | X8: TRUE | Y8: Generated | Z8: =AVERAGE(AA8:AC8) -> 7 | AA8: 7 | AB8: 7 | AC8: 7 | AD8: =(AG8-AE8)/60 -> 0.036183333 | AE8: 174.991 | AF8: 174.991 | AG8: 177.162 | AH8: 1 | AI8: TRUE | AJ8: TRUE | AK8: Generated | AL8: =AVERAGE(AM8:AO8) -> 7 | AM8: 7 | AN8: 7 | AO8: 7 | AP8: =(AS8-AQ8)/60 -> 7.2256 | AQ8: 11.666 | AR8: 424.828 | AS8: 445.202 | AT8: 16 | AU8: TRUE | AV8: TRUE | AW8: Generated | AX8: =AVERAGE(AY8:BA8) -> 5.6666667 | AY8: 5 | AZ8: 7 | BA8: 5 | BB8: =(BE8-BC8)/60 -> 3.6221333 | BC8: 1.597 | BD8: 217.002 | BE8: 218.925 | BF8: 4 | BG8: TRUE | BH8: TRUE | BI8: Generated | BJ8: =AVERAGE(BK8:BM8) -> 7 | BK8: 7 | BL8: 7 | BM8: 7 | BN8: =(BQ8-BO8)/60 -> 8.1237833 | BO8: 2.387 | BP8: 488.287 | BQ8: 489.814 | BR8: 19 | BS8: TRUE | BT8: TRUE | BU8: Manual | BV8: =AVERAGE(BW8:BY8) -> 6.6666667 | BW8: 7 | BX8: 7 | BY8: 6 | BZ8: Strongly Agree | CA8: Strongly disagree | CB8: Strongly Agree | CC8: Disagree | CD8: Strongly Agree | CE8: Disagree | CF8: Agree | CG8: Strongly disagree | CH8: Agree | CI8: Disagree | CJ8: =COUNTIF(X8,TRUE)+COUNTIF(AJ8,TRUE)+COUNTIF(AV8,TRUE)+COUNTIF(BH8,TRUE)+COUNTIF(BT8,TRUE) -> 5 | CK8: =(VLOOKUP(BZ8,References!$A$1:$C$6,2)+VLOOKUP(CA8,References!$A$1:$C$6,3)+VLOOKUP(CB8,References!$A$1:$C$6,2)+VLOOKUP(CC8,References!$A$1:$C$6,3)+VLOOKUP(CD8,References!$A$1:$C$6,2)+VLOOKUP(CE8,References!$A$1:$C$6,3)+VLOOKUP(CF8,References!$A$1:$C$6,2)+VLOOKUP(CG8,References!$A$1:$C$6,3)+VLOOKUP(CH8,References!$A$1:$C$6,2)+VLOOKUP(CI8,References!$A$1:$C$6,3))*2.5 -> 65 | CL8: new documentation is very straightforward. example code snippets are useful for getting started and making quick modifications. also, adding support for older python version allowing me to use lab machines was nice. | CM8: there was some confusion on the difference in when to use the simple and more complex PCP structures. | CN8: again, new documentation looks great! made it a lot easier this time around, haha (especially since i wasn't generating json by hand).
A9: 10211 | B9: R8 | C9: =A9/60 -> 170.18333 | D9: =(G9-E9)/60 -> 4.3347 | E9: 141.237 | F9: 399.071 | G9: 401.319 | H9: 10 | I9: 0.1.9 | J9: Senior | K9: Computer Science | L9: Male | M9: =(P9-N9)/60 -> 0.26423333 | N9: 108.672 | O9: 108.672 | P9: 124.526 | Q9: 1 | R9: =(U9-S9)/60 -> 3.571 | S9: 33.348 | T9: 238.973 | U9: 247.608 | V9: 2 | W9: TRUE | X9: TRUE | Y9: Generated | Z9: =AVERAGE(AA9:AC9) -> 7 | AA9: 7 | AB9: 7 | AC9: 7 | AD9: =(AG9-AE9)/60 -> 7.5306667 | AE9: 633.169 | AF9: 1077.781 | AG9: 1085.009 | AH9: 2 | AI9: TRUE | AJ9: TRUE | AK9: Generated | AL9: =AVERAGE(AM9:AO9) -> 7 | AM9: 7 | AN9: 7 | AO9: 7 | AP9: =(AS9-AQ9)/60 -> 0.12491667 | AQ9: 681.559 | AR9: 682.5 | AS9: 689.054 | AT9: 2 | AU9: TRUE | AV9: TRUE | AW9: Generated | AX9: =AVERAGE(AY9:BA9) -> 6.6666667 | AY9: 7 | AZ9: 7 | BA9: 6 | BB9: =(BE9-BC9)/60 -> 0.07795 | BC9: 183.095 | BD9: 184.053 | BE9: 187.772 | BF9: 2 | BG9: TRUE | BH9: TRUE | BI9: Generated | BJ9: =AVERAGE(BK9:BM9) -> 7 | BK9: 7 | BL9: 7 | BM9: 7 | BN9: =(BQ9-BO9)/60 -> 12.454583 | BO9: 1121.743 | BP9: 1862.954 | BQ9: 1869.018 | BR9: 3 | BS9: TRUE | BT9: TRUE | BU9: Generated | BV9: =AVERAGE(BW9:BY9) -> 6.3333333 | BW9: 6 | BX9: 7 | BY9: 6 | BZ9: Agree | CA9: Strongly disagree | CB9: Strongly Agree | CC9: Strongly disagree | CD9: Strongly Agree | CE9: Disagree | CF9: Agree | CG9: Disagree | CH9: Strongly Agree | CI9: Strongly disagree | CJ9: =COUNTIF(X9,TRUE)+COUNTIF(AJ9,TRUE)+COUNTIF(AV9,TRUE)+COUNTIF(BH9,TRUE)+COUNTIF(BT9,TRUE) -> 5 | CK9: =(VLOOKUP(BZ9,References!$A$1:$C$6,2)+VLOOKUP(CA9,References!$A$1:$C$6,3)+VLOOKUP(CB9,References!$A$1:$C$6,2)+VLOOKUP(CC9,References!$A$1:$C$6,3)+VLOOKUP(CD9,References!$A$1:$C$6,2)+VLOOKUP(CE9,References!$A$1:$C$6,3)+VLOOKUP(CF9,References!$A$1:$C$6,2)+VLOOKUP(CG9,References!$A$1:$C$6,3)+VLOOKUP(CH9,References!$A$1:$C$6,2)+VLOOKUP(CI9,References!$A$1:$C$6,3))*2.5 -> 67.5 | CL9: Very concise and helpful documentation is great for enabling a new user to make simple or complex password policies. | CM9: Some of the error messages were slightly unclear, but nothing major.
A10: 2406 | B10: R9 | C10: =A10/60 -> 40.1 | D10: =(G10-E10)/60 -> 0.69885 | E10: 84.724 | F10: 116.284 | G10: 126.655 | H10: 10 | I10: 0.1.9 | J10: Senior | K10: Computer Science | L10: Male | M10: =(P10-N10)/60 -> 0.19523333 | N10: 0 | O10: 0 | P10: 11.714 | Q10: 0 | R10: =(U10-S10)/60 -> 1.5413667 | S10: 15.876 | T10: 83.129 | U10: 108.358 | V10: 4 | W10: TRUE | X10: TRUE | Y10: Manual | Z10: =AVERAGE(AA10:AC10) -> 7 | AA10: 7 | AB10: 7 | AC10: 7 | AD10: =(AG10-AE10)/60 -> 3.8604167 | AE10: 15.284 | AF10: 242.668 | AG10: 246.909 | AH10: 26 | AI10: TRUE | AJ10: TRUE | AK10: Manual | AL10: =AVERAGE(AM10:AO10) -> 4.3333333 | AM10: 3 | AN10: 3 | AO10: 7 | AP10: =(AS10-AQ10)/60 -> 5.3168 | AQ10: 605.605 | AR10: 907.938 | AS10: 924.613 | AT10: 5 | AU10: TRUE | AV10: TRUE | AW10: Generated | AX10: =AVERAGE(AY10:BA10) -> 5.3333333 | AY10: 4 | AZ10: 5 | BA10: 7 | BB10: =(BE10-BC10)/60 -> 0.026466667 | BC10: 126.585 | BD10: 126.585 | BE10: 128.173 | BF10: 1 | BG10: TRUE | BH10: TRUE | BI10: Generated | BJ10: =AVERAGE(BK10:BM10) -> 6.3333333 | BK10: 6 | BL10: 6 | BM10: 7 | BN10: =(BQ10-BO10)/60 -> 6.0674 | BO10: 96.138 | BP10: 111.722 | BQ10: 460.182 | BR10: 3 | BS10: TRUE | BT10: TRUE | BU10: Generated | BV10: =AVERAGE(BW10:BY10) -> 4 | BW10: 3 | BX10: 4 | BY10: 5 | BZ10: Agree | CA10: Neither Agree nor Disagree | CB10: Agree | CC10: Strongly disagree | CD10: Neither Agree nor Disagree | CE10: Neither Agree nor Disagree | CF10: Neither Agree nor Disagree | CG10: Disagree | CH10: Agree | CI10: Agree | CJ10: =COUNTIF(X10,TRUE)+COUNTIF(AJ10,TRUE)+COUNTIF(AV10,TRUE)+COUNTIF(BH10,TRUE)+COUNTIF(BT10,TRUE) -> 5 | CK10: =(VLOOKUP(BZ10,References!$A$1:$C$6,2)+VLOOKUP(CA10,References!$A$1:$C$6,3)+VLOOKUP(CB10,References!$A$1:$C$6,2)+VLOOKUP(CC10,References!$A$1:$C$6,3)+VLOOKUP(CD10,References!$A$1:$C$6,2)+VLOOKUP(CE10,References!$A$1:$C$6,3)+VLOOKUP(CF10,References!$A$1:$C$6,2)+VLOOKUP(CG10,References!$A$1:$C$6,3)+VLOOKUP(CH10,References!$A$1:$C$6,2)+VLOOKUP(CI10,References!$A$1:$C$6,3))*2.5 -> 62.5 | CL10: It made it far easier to generate more complicated password policies, granted you knew how to use it. | CM10: Small details like PCPCharsetRequirements vs PCPSubsetRequirements had me confused for a bit, but then I caught on. | CN10: No
A11: 3923 | B11: R10 | C11: =A11/60 -> 65.383333 | D11: =(G11-E11)/60 -> 0.36218333 | E11: 66.739 | F11: 87.483 | G11: 88.47 | H11: 5 | I11: 0.1.9 | J11: Senior | K11: Computer Science | L11: Male | M11: =(P11-N11)/60 -> 0.19998333 | N11: 0 | O11: 0 | P11: 11.999 | Q11: 0 | R11: =(U11-S11)/60 -> 1.96625 | S11: 6.537 | T11: 121.899 | U11: 124.512 | V11: 3 | W11: TRUE | X11: TRUE | Y11: Generated | Z11: =AVERAGE(AA11:AC11) -> 7 | AA11: 7 | AB11: 7 | AC11: 7 | AD11: =(AG11-AE11)/60 -> 0.043316667 | AE11: 177.12 | AF11: 177.12 | AG11: 179.719 | AH11: 1 | AI11: TRUE | AJ11: TRUE | AK11: Generated | AL11: =AVERAGE(AM11:AO11) -> 7 | AM11: 7 | AN11: 7 | AO11: 7 | AP11: =(AS11-AQ11)/60 -> 28.670967 | AQ11: 317.168 | AR11: 2030.641 | AS11: 2037.426 | AT11: 9 | AU11: TRUE | AV11: TRUE | AW11: Generated | AX11: =AVERAGE(AY11:BA11) -> 2.6666667 | AY11: 4 | AZ11: 2 | BA11: 2 | BB11: =(BE11-BC11)/60 -> 1.49 | BC11: 10.645 | BD11: 98.061 | BE11: 100.045 | BF11: 4 | BG11: TRUE | BH11: TRUE | BI11: Generated | BJ11: =AVERAGE(BK11:BM11) -> 7 | BK11: 7 | BL11: 7 | BM11: 7 | BN11: =(BQ11-BO11)/60 -> 11.479083 | BO11: 292.764 | BP11: 978.654 | BQ11: 981.509 | BR11: 4 | BS11: FALSE | BT11: FALSE | BU11: Generated | BV11: =AVERAGE(BW11:BY11) -> 7 | BW11: 7 | BX11: 7 | BY11: 7 | BZ11: Neither Agree nor Disagree | CA11: Agree | CB11: Agree | CC11: Strongly disagree | CD11: Disagree | CE11: Agree | CF11: Neither Agree nor Disagree | CG11: Agree | CH11: Strongly disagree | CI11: Agree | CJ11: =COUNTIF(X11,TRUE)+COUNTIF(AJ11,TRUE)+COUNTIF(AV11,TRUE)+COUNTIF(BH11,TRUE)+COUNTIF(BT11,TRUE) -> 4 | CK11: =(VLOOKUP(BZ11,References!$A$1:$C$6,2)+VLOOKUP(CA11,References!$A$1:$C$6,3)+VLOOKUP(CB11,References!$A$1:$C$6,2)+VLOOKUP(CC11,References!$A$1:$C$6,3)+VLOOKUP(CD11,References!$A$1:$C$6,2)+VLOOKUP(CE11,References!$A$1:$C$6,3)+VLOOKUP(CF11,References!$A$1:$C$6,2)+VLOOKUP(CG11,References!$A$1:$C$6,3)+VLOOKUP(CH11,References!$A$1:$C$6,2)+VLOOKUP(CI11,References!$A$1:$C$6,3))*2.5 -> 35 | CL11: I liked how easy it was with the SimplePCP. | CM11: The inconsistency in syntax between PCP and SimplePCP made the usage unnecessarily cumbersome. SimplePCP should be able to use the "alphabet" charset. When removing characters, max_allowed should be able to restrict characters. | CN11: As far as this survey goes, I feel like a lot of the questions were almost exactly like the documentation and the ones that were not were the only hard ones. Almost too similar
A12: 3392 | B12: R11 | C12: =A12/60 -> 56.533333 | D12: =(G12-E12)/60 -> 12.8791 | E12: 50.427 | F12: 818.352 | G12: 823.173 | H12: 21 | I12: 0.1.9 | J12: PhD student | K12: Computer Science | L12: Male | M12: =(P12-N12)/60 -> 0.22146667 | N12: 76.546 | O12: 76.546 | P12: 89.834 | Q12: 1 | R12: =(U12-S12)/60 -> 12.175617 | S12: 72.991 | T12: 801.058 | U12: 803.528 | V12: 27 | W12: TRUE | X12: FALSE | Y12: Generated | Z12: =AVERAGE(AA12:AC12) -> 6.6666667 | AA12: 6 | AB12: 7 | AC12: 7 | AD12: =(AG12-AE12)/60 -> 8.7749667 | AE12: 57.989 | AF12: 552.259 | AG12: 584.487 | AH12: 26 | AI12: TRUE | AJ12: FALSE | AK12: Generated | AL12: =AVERAGE(AM12:AO12) -> 2 | AM12: 1 | AN12: 1 | AO12: 4 | AP12: =(AS12-AQ12)/60 -> 1.2277833 | AQ12: 30.337 | AR12: 82.324 | AS12: 104.004 | AT12: 9 | AU12: TRUE | AV12: FALSE | AW12: Generated | AX12: =AVERAGE(AY12:BA12) -> 4 | AY12: 4 | AZ12: 4 | BA12: 4 | BB12: =(BE12-BC12)/60 -> 5.9880167 | BC12: 2.695 | BD12: 357.983 | BE12: 361.976 | BF12: 20 | BG12: TRUE | BH12: TRUE | BI12: Generated | BJ12: =AVERAGE(BK12:BM12) -> 5 | BK12: 5 | BL12: 5 | BM12: 5 | BN12: =(BQ12-BO12)/60 -> 2.9679833 | BO12: 2.036 | BP12: 178.358 | BQ12: 180.115 | BR12: 14 | BS12: TRUE | BT12: FALSE | BU12: Generated | BV12: =AVERAGE(BW12:BY12) -> 5 | BW12: 5 | BX12: 5 | BY12: 5 | BZ12: Neither Agree nor Disagree | CA12: Agree | CB12: Disagree | CC12: Neither Agree nor Disagree | CD12: Neither Agree nor Disagree | CE12: Disagree | CF12: Strongly disagree | CG12: Strongly disagree | CH12: Neither Agree nor Disagree | CI12: Strongly disagree | CJ12: =COUNTIF(X12,TRUE)+COUNTIF(AJ12,TRUE)+COUNTIF(AV12,TRUE)+COUNTIF(BH12,TRUE)+COUNTIF(BT12,TRUE) -> 1 | CK12: =(VLOOKUP(BZ12,References!$A$1:$C$6,2)+VLOOKUP(CA12,References!$A$1:$C$6,3)+VLOOKUP(CB12,References!$A$1:$C$6,2)+VLOOKUP(CC12,References!$A$1:$C$6,3)+VLOOKUP(CD12,References!$A$1:$C$6,2)+VLOOKUP(CE12,References!$A$1:$C$6,3)+VLOOKUP(CF12,References!$A$1:$C$6,2)+VLOOKUP(CG12,References!$A$1:$C$6,3)+VLOOKUP(CH12,References!$A$1:$C$6,2)+VLOOKUP(CI12,References!$A$1:$C$6,3))*2.5 -> 47.5 | CL12: It can generate random passwords with the requirements I pass. | CM12: The need for coding to set the requirements.
A13: 2395 | B13: R12 | C13: =A13/60 -> 39.916667 | D13: =(G13-E13)/60 -> 1.1130667 | E13: 3.611 | F13: 62.608 | G13: 70.395 | H13: 10 | I13: 0.1.9 | J13: PhD student | K13: Computer Science | L13: Male | M13: =(P13-N13)/60 -> 1.01725 | N13: 0 | O13: 0 | P13: 61.035 | Q13: 0 | R13: =(U13-S13)/60 -> 0.76388333 | S13: 124.006 | T13: 127.016 | U13: 169.839 | V13: 3 | W13: TRUE | X13: TRUE | Y13: Manual | Z13: =AVERAGE(AA13:AC13) -> 7 | AA13: 7 | AB13: 7 | AC13: 7 | AD13: =(AG13-AE13)/60 -> 3.9636667 | AE13: 26.202 | AF13: 259.834 | AG13: 264.022 | AH13: 5 | AI13: TRUE | AJ13: TRUE | AK13: Manual | AL13: =AVERAGE(AM13:AO13) -> 7 | AM13: 7 | AN13: 7 | AO13: 7 | AP13: =(AS13-AQ13)/60 -> 10.460433 | AQ13: 37.871 | AR13: 560.736 | AS13: 665.497 | AT13: 17 | AU13: TRUE | AV13: TRUE | AW13: Manual | AX13: =AVERAGE(AY13:BA13) -> 6 | AY13: 6 | AZ13: 6 | BA13: 6 | BB13: =(BE13-BC13)/60 -> 3.0015833 | BC13: 129.1 | BD13: 305.788 | BE13: 309.195 | BF13: 4 | BG13: TRUE | BH13: TRUE | BI13: Generated | BJ13: =AVERAGE(BK13:BM13) -> 6 | BK13: 6 | BL13: 6 | BM13: 6 | BN13: =(BQ13-BO13)/60 -> 8.65575 | BO13: 53.601 | BP13: 561.695 | BQ13: 572.946 | BR13: 16 | BS13: TRUE | BT13: TRUE | BU13: Manual | BV13: =AVERAGE(BW13:BY13) -> 6 | BW13: 6 | BX13: 6 | BY13: 6 | BZ13: Strongly Agree | CA13: Disagree | CB13: Agree | CC13: Strongly disagree | CD13: Strongly Agree | CE13: Disagree | CF13: Agree | CG13: Strongly disagree | CH13: Agree | CI13: Disagree | CJ13: =COUNTIF(X13,TRUE)+COUNTIF(AJ13,TRUE)+COUNTIF(AV13,TRUE)+COUNTIF(BH13,TRUE)+COUNTIF(BT13,TRUE) -> 5 | CK13: =(VLOOKUP(BZ13,References!$A$1:$C$6,2)+VLOOKUP(CA13,References!$A$1:$C$6,3)+VLOOKUP(CB13,References!$A$1:$C$6,2)+VLOOKUP(CC13,References!$A$1:$C$6,3)+VLOOKUP(CD13,References!$A$1:$C$6,2)+VLOOKUP(CE13,References!$A$1:$C$6,3)+VLOOKUP(CF13,References!$A$1:$C$6,2)+VLOOKUP(CG13,References!$A$1:$C$6,3)+VLOOKUP(CH13,References!$A$1:$C$6,2)+VLOOKUP(CI13,References!$A$1:$C$6,3))*2.5 -> 70 | CL13: The ease of implementing the password policy using library | CM13: No particular thing I disliked about it | CN13: Looks super helpful to implement password policies using this library
A14: 3511 | B14: R13 | C14: =A14/60 -> 58.516667 | D14: =(G14-E14)/60 -> 0.85781667 | E14: 4.238 | F14: 50.832 | G14: 55.707 | H14: 7 | I14: 0.1.9 | J14: MS student | K14: Computer Science | L14: Male | M14: =(P14-N14)/60 -> 0.42911667 | N14: 1.4 | O14: 17.194 | P14: 27.147 | Q14: 7 | R14: =(U14-S14)/60 -> 2.4739667 | S14: 2.403 | T14: 141.04 | U14: 150.841 | V14: 7 | W14: TRUE | X14: TRUE | Y14: Manual | Z14: =AVERAGE(AA14:AC14) -> 7 | AA14: 7 | AB14: 7 | AC14: 7 | AD14: =(AG14-AE14)/60 -> 16.6323 | AE14: 16.205 | AF14: 993.554 | AG14: 1014.143 | AH14: 48 | AI14: TRUE | AJ14: TRUE | AK14: Manual | AL14: =AVERAGE(AM14:AO14) -> 6.6666667 | AM14: 7 | AN14: 6 | AO14: 7 | AP14: =(AS14-AQ14)/60 -> 10.07025 | AQ14: 1.61 | AR14: 599.548 | AS14: 605.825 | AT14: 24 | AU14: TRUE | AV14: TRUE | AW14: Manual | AX14: =AVERAGE(AY14:BA14) -> 6 | AY14: 6 | AZ14: 5 | BA14: 7 | BB14: =(BE14-BC14)/60 -> 12.6988 | BC14: 1.658 | BD14: 758.015 | BE14: 763.586 | BF14: 68 | BG14: TRUE | BH14: TRUE | BI14: Manual | BJ14: =AVERAGE(BK14:BM14) -> 5 | BK14: 5 | BL14: 5 | BM14: 5 | BN14: =(BQ14-BO14)/60 -> 3.8229667 | BO14: 6.637 | BP14: 218.973 | BQ14: 236.015 | BR14: 18 | BS14: TRUE | BT14: TRUE | BU14: Manual | BV14: =AVERAGE(BW14:BY14) -> 7 | BW14: 7 | BX14: 7 | BY14: 7 | BZ14: Agree | CA14: Strongly disagree | CB14: Agree | CC14: Disagree | CD14: Agree | CE14: Disagree | CF14: Strongly Agree | CG14: Strongly disagree | CH14: Agree | CI14: Disagree | CJ14: =COUNTIF(X14,TRUE)+COUNTIF(AJ14,TRUE)+COUNTIF(AV14,TRUE)+COUNTIF(BH14,TRUE)+COUNTIF(BT14,TRUE) -> 5 | CK14: =(VLOOKUP(BZ14,References!$A$1:$C$6,2)+VLOOKUP(CA14,References!$A$1:$C$6,3)+VLOOKUP(CB14,References!$A$1:$C$6,2)+VLOOKUP(CC14,References!$A$1:$C$6,3)+VLOOKUP(CD14,References!$A$1:$C$6,2)+VLOOKUP(CE14,References!$A$1:$C$6,3)+VLOOKUP(CF14,References!$A$1:$C$6,2)+VLOOKUP(CG14,References!$A$1:$C$6,3)+VLOOKUP(CH14,References!$A$1:$C$6,2)+VLOOKUP(CI14,References!$A$1:$C$6,3))*2.5 -> 75 | CL14: I liked the overall system and its ease of use. I could easily create a password policy after reading the documentation. The documentation was pretty straightforward. | CM14: I didn't use the library because I feel like it's a bit of work than just writing it in a JSON file. So, maybe there is a way to make the python library easier to use.
A15: 4717 | B15: R14 | C15: =A15/60 -> 78.616667 | D15: =(G15-E15)/60 -> 1.3569667 | E15: 15.752 | F15: 95.3 | G15: 97.17 | H15: 12 | I15: 0.1.9 | J15: PhD student | K15: Computer Science | L15: Male | M15: =(P15-N15)/60 -> 0.084283333 | N15: 32.521 | O15: 32.521 | P15: 37.578 | Q15: 1 | R15: =(U15-S15)/60 -> 0.55946667 | S15: 109.395 | T15: 140.175 | U15: 142.963 | V15: 10 | W15: TRUE | X15: TRUE | Y15: Manual | Z15: =AVERAGE(AA15:AC15) -> 7 | AA15: 7 | AB15: 7 | AC15: 7 | AD15: =(AG15-AE15)/60 -> 1.0162167 | AE15: 79.398 | AF15: 136.607 | AG15: 140.371 | AH15: 10 | AI15: TRUE | AJ15: TRUE | AK15: Manual | AL15: =AVERAGE(AM15:AO15) -> 7 | AM15: 7 | AN15: 7 | AO15: 7 | AP15: =(AS15-AQ15)/60 -> 39.197033 | AQ15: 50.38 | AR15: 2400.1 | AS15: 2402.202 | AT15: 136 | AU15: TRUE | AV15: TRUE | AW15: Generated | AX15: =AVERAGE(AY15:BA15) -> 7 | AY15: 7 | AZ15: 7 | BA15: 7 | BB15: =(BE15-BC15)/60 -> 0.33898333 | BC15: 50.803 | BD15: 67.534 | BE15: 71.142 | BF15: 4 | BG15: TRUE | BH15: TRUE | BI15: Manual | BJ15: =AVERAGE(BK15:BM15) -> 7 | BK15: 7 | BL15: 7 | BM15: 7 | BN15: =(BQ15-BO15)/60 -> 18.084467 | BO15: 25.749 | BP15: 1107.049 | BQ15: 1110.817 | BR15: 64 | BS15: FALSE | BT15: FALSE | BU15: Generated | BV15: =AVERAGE(BW15:BY15) -> 6 | BW15: 7 | BX15: 4 | BY15: 7 | BZ15: Strongly Agree | CA15: Strongly disagree | CB15: Strongly Agree | CC15: Strongly disagree | CD15: Strongly Agree | CE15: Strongly disagree | CF15: Strongly Agree | CG15: Strongly disagree | CH15: Agree | CI15: Strongly disagree | CJ15: =COUNTIF(X15,TRUE)+COUNTIF(AJ15,TRUE)+COUNTIF(AV15,TRUE)+COUNTIF(BH15,TRUE)+COUNTIF(BT15,TRUE) -> 4 | CK15: =(VLOOKUP(BZ15,References!$A$1:$C$6,2)+VLOOKUP(CA15,References!$A$1:$C$6,3)+VLOOKUP(CB15,References!$A$1:$C$6,2)+VLOOKUP(CC15,References!$A$1:$C$6,3)+VLOOKUP(CD15,References!$A$1:$C$6,2)+VLOOKUP(CE15,References!$A$1:$C$6,3)+VLOOKUP(CF15,References!$A$1:$C$6,2)+VLOOKUP(CG15,References!$A$1:$C$6,3)+VLOOKUP(CH15,References!$A$1:$C$6,2)+VLOOKUP(CI15,References!$A$1:$C$6,3))*2.5 -> 67.5 | CL15: I liked how simply we can specify rules for password policy using this library. | CM15: I was using "numbers" in places of "digits" in some of the questions. I felt using "number" to specify the number input might be easier.
A16: 2815 | B16: R15 | C16: =A16/60 -> 46.916667 | D16: =(G16-E16)/60 -> 1.60235 | E16: 7.905 | F16: 99.896 | G16: 104.046 | H16: 9 | I16: 0.1.9 | J16: PhD student | K16: Computer Engineering | L16: Female | M16: =(P16-N16)/60 -> 0.26346667 | N16: 18.047 | O16: 18.047 | P16: 33.855 | Q16: 1 | R16: =(U16-S16)/60 -> 0.23546667 | S16: 136.033 | T16: 136.033 | U16: 150.161 | V16: 1 | W16: TRUE | X16: TRUE | Y16: Generated | Z16: =AVERAGE(AA16:AC16) -> 6.3333333 | AA16: 6 | AB16: 7 | AC16: 6 | AD16: =(AG16-AE16)/60 -> 2.40045 | AE16: 16.36 | AF16: 153.544 | AG16: 160.387 | AH16: 13 | AI16: TRUE | AJ16: TRUE | AK16: Manual | AL16: =AVERAGE(AM16:AO16) -> 6.6666667 | AM16: 7 | AN16: 7 | AO16: 6 | AP16: =(AS16-AQ16)/60 -> 2.91835 | AQ16: 32.459 | AR16: 201.565 | AS16: 207.56 | AT16: 14 | AU16: TRUE | AV16: TRUE | AW16: Manual | AX16: =AVERAGE(AY16:BA16) -> 5.3333333 | AY16: 4 | AZ16: 5 | BA16: 7 | BB16: =(BE16-BC16)/60 -> 1.6182667 | BC16: 360.175 | BD16: 455.867 | BE16: 457.271 | BF16: 12 | BG16: TRUE | BH16: TRUE | BI16: Manual | BJ16: =AVERAGE(BK16:BM16) -> 6.6666667 | BK16: 6 | BL16: 7 | BM16: 7 | BN16: =(BQ16-BO16)/60 -> 20.176383 | BO16: 1.437 | BP16: 1210.428 | BQ16: 1212.02 | BR16: 23 | BS16: TRUE | BT16: FALSE | BU16: Manual | BV16: =AVERAGE(BW16:BY16) -> 1.3333333 | BW16: 1 | BX16: 1 | BY16: 2 | BZ16: Neither Agree nor Disagree | CA16: Agree | CB16: Disagree | CC16: Agree | CD16: Agree | CE16: Disagree | CF16: Disagree | CG16: Agree | CH16: Neither Agree nor Disagree | CI16: Agree | CJ16: =COUNTIF(X16,TRUE)+COUNTIF(AJ16,TRUE)+COUNTIF(AV16,TRUE)+COUNTIF(BH16,TRUE)+COUNTIF(BT16,TRUE) -> 4 | CK16: =(VLOOKUP(BZ16,References!$A$1:$C$6,2)+VLOOKUP(CA16,References!$A$1:$C$6,3)+VLOOKUP(CB16,References!$A$1:$C$6,2)+VLOOKUP(CC16,References!$A$1:$C$6,3)+VLOOKUP(CD16,References!$A$1:$C$6,2)+VLOOKUP(CE16,References!$A$1:$C$6,3)+VLOOKUP(CF16,References!$A$1:$C$6,2)+VLOOKUP(CG16,References!$A$1:$C$6,3)+VLOOKUP(CH16,References!$A$1:$C$6,2)+VLOOKUP(CI16,References!$A$1:$C$6,3))*2.5 -> 35 | CL16: Character sets could be constructed easily with length restrictions. | CM16: It gets complicated with multiple rules. The difference between simplepcp and other pcp functions is not evident.
A17: 2053 | B17: R16 | C17: =A17/60 -> 34.216667 | D17: =(G17-E17)/60 -> 1.45195 | E17: 3.928 | F17: 83.099 | G17: 91.045 | H17: 11 | I17: 0.1.9 | J17: MS student | K17: Computer Science | L17: Male | M17: =(P17-N17)/60 -> 0.12978333 | N17: 13.833 | O17: 13.833 | P17: 21.62 | Q17: 1 | R17: =(U17-S17)/60 -> 1.6006167 | S17: 3.401 | T17: 97.541 | U17: 99.438 | V17: 2 | W17: TRUE | X17: TRUE | Y17: Generated | Z17: =AVERAGE(AA17:AC17) -> 7 | AA17: 7 | AB17: 7 | AC17: 7 | AD17: =(AG17-AE17)/60 -> 0.77306667 | AE17: 34.389 | AF17: 80.018 | AG17: 80.773 | AH17: 3 | AI17: TRUE | AJ17: TRUE | AK17: Generated | AL17: =AVERAGE(AM17:AO17) -> 6.6666667 | AM17: 6 | AN17: 7 | AO17: 7 | AP17: =(AS17-AQ17)/60 -> 14.227167 | AQ17: 69.692 | AR17: 909.018 | AS17: 923.322 | AT17: 8 | AU17: TRUE | AV17: TRUE | AW17: Generated | AX17: =AVERAGE(AY17:BA17) -> 6.3333333 | AY17: 7 | AZ17: 6 | BA17: 6 | BB17: =(BE17-BC17)/60 -> 0.70425 | BC17: 284.438 | BD17: 320.734 | BE17: 326.693 | BF17: 7 | BG17: TRUE | BH17: TRUE | BI17: Generated | BJ17: =AVERAGE(BK17:BM17) -> 6.3333333 | BK17: 6 | BL17: 6 | BM17: 7 | BN17: =(BQ17-BO17)/60 -> 1.1578167 | BO17: 109.883 | BP17: 177.767 | BQ17: 179.352 | BR17: 4 | BS17: TRUE | BT17: FALSE | BU17: Generated | BV17: =AVERAGE(BW17:BY17) -> 6.3333333 | BW17: 6 | BX17: 6 | BY17: 7 | BZ17: Agree | CA17: Disagree | CB17: Agree | CC17: Strongly disagree | CD17: Agree | CE17: Disagree | CF17: Strongly Agree | CG17: Disagree | CH17: Agree | CI17: Agree | CJ17: =COUNTIF(X17,TRUE)+COUNTIF(AJ17,TRUE)+COUNTIF(AV17,TRUE)+COUNTIF(BH17,TRUE)+COUNTIF(BT17,TRUE) -> 4 | CK17: =(VLOOKUP(BZ17,References!$A$1:$C$6,2)+VLOOKUP(CA17,References!$A$1:$C$6,3)+VLOOKUP(CB17,References!$A$1:$C$6,2)+VLOOKUP(CC17,References!$A$1:$C$6,3)+VLOOKUP(CD17,References!$A$1:$C$6,2)+VLOOKUP(CE17,References!$A$1:$C$6,3)+VLOOKUP(CF17,References!$A$1:$C$6,2)+VLOOKUP(CG17,References!$A$1:$C$6,3)+VLOOKUP(CH17,References!$A$1:$C$6,2)+VLOOKUP(CI17,References!$A$1:$C$6,3))*2.5 -> 67.5 | CL17: The system is well documented and the code is well written and modular. | CM17: Too much modularity makes it somewhat difficult. Might need some sort of technical document. | CN17: No
A18: 542 | B18: R17 | C18: =A18/60 -> 9.0333333 | D18: =(G18-E18)/60 -> 0.48701667 | E18: 17.89 | F18: 17.89 | G18: 47.111 | H18: 1 | I18: 0.1.9 | J18: PhD student | K18: Computer Science | L18: Male | M18: =(P18-N18)/60 -> 0.15383333 | N18: 0 | O18: 0 | P18: 9.23 | Q18: 0 | R18: =(U18-S18)/60 -> 0.3439 | S18: 33.736 | T18: 48.633 | U18: 54.37 | V18: 2 | W18: TRUE | X18: TRUE | Y18: Manual | Z18: =AVERAGE(AA18:AC18) -> 4.3333333 | AA18: 4 | AB18: 5 | AC18: 4 | AD18: =(AG18-AE18)/60 -> 1.1014333 | AE18: 41.23 | AF18: 103.826 | AG18: 107.316 | AH18: 4 | AI18: TRUE | AJ18: TRUE | AK18: Generated | AL18: =AVERAGE(AM18:AO18) -> 5.3333333 | AM18: 6 | AN18: 5 | AO18: 5 | AP18: =(AS18-AQ18)/60 -> 0.51475 | AQ18: 5.349 | AR18: 34.149 | AS18: 36.234 | AT18: 2 | AU18: TRUE | AV18: TRUE | AW18: Generated | AX18: =AVERAGE(AY18:BA18) -> 5.3333333 | AY18: 6 | AZ18: 5 | BA18: 5 | BB18: =(BE18-BC18)/60 -> 0.037466667 | BC18: 30.662 | BD18: 30.662 | BE18: 32.91 | BF18: 1 | BG18: TRUE | BH18: TRUE | BI18: Generated | BJ18: =AVERAGE(BK18:BM18) -> 6.3333333 | BK18: 6 | BL18: 7 | BM18: 6 | BN18: =(BQ18-BO18)/60 -> 0.039783333 | BO18: 21.129 | BP18: 21.129 | BQ18: 23.516 | BR18: 1 | BS18: TRUE | BT18: FALSE | BU18: Generated | BV18: =AVERAGE(BW18:BY18) -> 6.6666667 | BW18: 6 | BX18: 7 | BY18: 7 | BZ18: Agree | CA18: Neither Agree nor Disagree | CB18: Agree | CC18: Disagree | CD18: Agree | CE18: Disagree | CF18: Agree | CG18: Disagree | CH18: Strongly Agree | CI18: Neither Agree nor Disagree | CJ18: =COUNTIF(X18,TRUE)+COUNTIF(AJ18,TRUE)+COUNTIF(AV18,TRUE)+COUNTIF(BH18,TRUE)+COUNTIF(BT18,TRUE) -> 4 | CK18: =(VLOOKUP(BZ18,References!$A$1:$C$6,2)+VLOOKUP(CA18,References!$A$1:$C$6,3)+VLOOKUP(CB18,References!$A$1:$C$6,2)+VLOOKUP(CC18,References!$A$1:$C$6,3)+VLOOKUP(CD18,References!$A$1:$C$6,2)+VLOOKUP(CE18,References!$A$1:$C$6,3)+VLOOKUP(CF18,References!$A$1:$C$6,2)+VLOOKUP(CG18,References!$A$1:$C$6,3)+VLOOKUP(CH18,References!$A$1:$C$6,2)+VLOOKUP(CI18,References!$A$1:$C$6,3))*2.5 -> 70 | CL18: Modularity of the system | CM18: Needed some learning before I could properly use it | CN18: I think the system does need some learning before starting and is extremely modular whic introduces extra complexity. However, overall the system is quite good.
A19: 1448 | B19: R18 | C19: =A19/60 -> 24.133333 | D19: =(G19-E19)/60 -> 0.51876667 | E19: 10.7 | F19: 31.432 | G19: 41.826 | H19: 7 | I19: 0.1.9 | J19: PhD student | K19: Computer Science | L19: Male | M19: =(P19-N19)/60 -> 0.33776667 | N19: 0 | O19: 0 | P19: 20.266 | Q19: 0 | R19: =(U19-S19)/60 -> 1.0250667 | S19: 16.295 | T19: 63.66 | U19: 77.799 | V19: 5 | W19: TRUE | X19: TRUE | Y19: Generated | Z19: =AVERAGE(AA19:AC19) -> 4.6666667 | AA19: 5 | AB19: 3 | AC19: 6 | AD19: =(AG19-AE19)/60 -> 1.2181333 | AE19: 22.624 | AF19: 76.222 | AG19: 95.712 | AH19: 6 | AI19: TRUE | AJ19: TRUE | AK19: Generated | AL19: =AVERAGE(AM19:AO19) -> 4.3333333 | AM19: 4 | AN19: 3 | AO19: 6 | AP19: =(AS19-AQ19)/60 -> 14.119517 | AQ19: 19.792 | AR19: 854.504 | AS19: 866.963 | AT19: 49 | AU19: TRUE | AV19: TRUE | AW19: Generated | AX19: =AVERAGE(AY19:BA19) -> 5 | AY19: 5 | AZ19: 4 | BA19: 6 | BB19: =(BE19-BC19)/60 -> 2.4772333 | BC19: 15.123 | BD19: 161.416 | BE19: 163.757 | BF19: 21 | BG19: TRUE | BH19: TRUE | BI19: Generated | BJ19: =AVERAGE(BK19:BM19) -> 5 | BK19: 5 | BL19: 6 | BM19: 4 | BN19: =(BQ19-BO19)/60 -> 0.04415 | BO19: 31 | BP19: 31 | BQ19: 33.649 | BR19: 1 | BS19: TRUE | BT19: TRUE | BU19: Generated | BV19: =AVERAGE(BW19:BY19) -> 5 | BW19: 6 | BX19: 4 | BY19: 5 | BZ19: Agree | CA19: Agree | CB19: Neither Agree nor Disagree | CC19: Disagree | CD19: Neither Agree nor Disagree | CE19: Neither Agree nor Disagree | CF19: Disagree | CG19: Agree | CH19: Neither Agree nor Disagree | CI19: Neither Agree nor Disagree | CJ19: =COUNTIF(X19,TRUE)+COUNTIF(AJ19,TRUE)+COUNTIF(AV19,TRUE)+COUNTIF(BH19,TRUE)+COUNTIF(BT19,TRUE) -> 5 | CK19: =(VLOOKUP(BZ19,References!$A$1:$C$6,2)+VLOOKUP(CA19,References!$A$1:$C$6,3)+VLOOKUP(CB19,References!$A$1:$C$6,2)+VLOOKUP(CC19,References!$A$1:$C$6,3)+VLOOKUP(CD19,References!$A$1:$C$6,2)+VLOOKUP(CE19,References!$A$1:$C$6,3)+VLOOKUP(CF19,References!$A$1:$C$6,2)+VLOOKUP(CG19,References!$A$1:$C$6,3)+VLOOKUP(CH19,References!$A$1:$C$6,2)+VLOOKUP(CI19,References!$A$1:$C$6,3))*2.5 -> 45 | CL19: Ease of use with the programming knowledge | CM19: Unnecessary overload for the normal JSON rules.
A20: 7527 | B20: R19 | C20: =A20/60 -> 125.45 | D20: =(G20-E20)/60 -> 0.62336667 | E20: 49.104 | F20: 84.875 | G20: 86.506 | H20: 6 | I20: 0.1.9 | J20: MS student | K20: Computer Science | L20: Female | M20: =(P20-N20)/60 -> 0.01215 | N20: 372.666 | O20: 372.666 | P20: 373.395 | Q20: 1 | R20: =(U20-S20)/60 -> 3.0827333 | S20: 46.652 | T20: 198.553 | U20: 231.616 | V20: 10 | W20: TRUE | X20: TRUE | Y20: Manual | Z20: =AVERAGE(AA20:AC20) -> 4 | AA20: 3 | AB20: 6 | AC20: 3 | AD20: =(AG20-AE20)/60 -> 8.9207667 | AE20: 55.493 | AF20: 576.393 | AG20: 590.739 | AH20: 31 | AI20: TRUE | AJ20: TRUE | AK20: Manual | AL20: =AVERAGE(AM20:AO20) -> 5 | AM20: 5 | AN20: 5 | AO20: 5 | AP20: =(AS20-AQ20)/60 -> 10.417983 | AQ20: 15.078 | AR20: 628.459 | AS20: 640.157 | AT20: 68 | AU20: TRUE | AV20: TRUE | AW20: Generated | AX20: =AVERAGE(AY20:BA20) -> 3.6666667 | AY20: 2 | AZ20: 2 | BA20: 7 | BB20: =(BE20-BC20)/60 -> 1.8387667 | BC20: 31.555 | BD20: 140.773 | BE20: 141.881 | BF20: 11 | BG20: TRUE | BH20: TRUE | BI20: Generated | BJ20: =AVERAGE(BK20:BM20) -> 7 | BK20: 7 | BL20: 7 | BM20: 7 | BN20: =(BQ20-BO20)/60 -> 68.885533 | BO20: 72.382 | BP20: 4203.419 | BQ20: 4205.514 | BR20: 190 | BS20: FALSE | BT20: FALSE | BU20: Manual | BV20: =AVERAGE(BW20:BY20) -> 1.6666667 | BW20: 1 | BX20: 2 | BY20: 2 | BZ20: Disagree | CA20: Disagree | CB20: Neither Agree nor Disagree | CC20: Neither Agree nor Disagree | CD20: Agree | CE20: Disagree | CF20: Agree | CG20: Disagree | CH20: Neither Agree nor Disagree | CI20: Neither Agree nor Disagree | CJ20: =COUNTIF(X20,TRUE)+COUNTIF(AJ20,TRUE)+COUNTIF(AV20,TRUE)+COUNTIF(BH20,TRUE)+COUNTIF(BT20,TRUE) -> 4 | CK20: =(VLOOKUP(BZ20,References!$A$1:$C$6,2)+VLOOKUP(CA20,References!$A$1:$C$6,3)+VLOOKUP(CB20,References!$A$1:$C$6,2)+VLOOKUP(CC20,References!$A$1:$C$6,3)+VLOOKUP(CD20,References!$A$1:$C$6,2)+VLOOKUP(CE20,References!$A$1:$C$6,3)+VLOOKUP(CF20,References!$A$1:$C$6,2)+VLOOKUP(CG20,References!$A$1:$C$6,3)+VLOOKUP(CH20,References!$A$1:$C$6,2)+VLOOKUP(CI20,References!$A$1:$C$6,3))*2.5 -> 60 | CL20: It is a better alternative to generate password policies. | CM20: N/A
A21: 47807 | B21: R20 | C21: =A21/60 -> 796.78333 | D21: =(G21-E21)/60 -> 3.74705 | E21: 12.814 | F21: 224.305 | G21: 237.637 | H21: 16 | I21: 0.1.9 | J21: MS student | K21: Computer Science | L21: Female | M21: =(P21-N21)/60 -> 0.07915 | N21: 0 | O21: 0 | P21: 4.749 | Q21: 0 | R21: =(U21-S21)/60 -> 3.5432667 | S21: 15.655 | T21: 227.241 | U21: 228.251 | V21: 16 | W21: FALSE | X21: FALSE | Y21: Generated | Z21: =AVERAGE(AA21:AC21) -> 5 | AA21: 4 | AB21: 6 | AC21: 5 | AD21: =(AG21-AE21)/60 -> 7.51835 | AE21: 5.181 | AF21: 392.819 | AG21: 456.282 | AH21: 7 | AI21: FALSE | AJ21: FALSE | AK21: Manual | AL21: =AVERAGE(AM21:AO21) -> 4 | AM21: 3 | AN21: 5 | AO21: 4 | AP21: =(AS21-AQ21)/60 -> 20.73725 | AQ21: 504.396 | AR21: 1744.807 | AS21: 1748.631 | AT21: 13 | AU21: FALSE | AV21: FALSE | AW21: Generated | AX21: =AVERAGE(AY21:BA21) -> 4.6666667 | AY21: 4 | AZ21: 5 | BA21: 5 | BB21: =(BE21-BC21)/60 -> 2.91955 | BC21: 29.077 | BD21: 190.627 | BE21: 204.25 | BF21: 11 | BG21: FALSE | BH21: FALSE | BI21: Manual | BJ21: =AVERAGE(BK21:BM21) -> 3.6666667 | BK21: 4 | BL21: 4 | BM21: 3 | BN21: =(BQ21-BO21)/60 -> 5.8105167 | BO21: 7.401 | BP21: 349.439 | BQ21: 356.032 | BR21: 30 | BS21: TRUE | BT21: TRUE | BU21: Manual | BV21: =AVERAGE(BW21:BY21) -> 3.6666667 | BW21: 3 | BX21: 4 | BY21: 4 | BZ21: Neither Agree nor Disagree | CA21: Agree | CB21: Neither Agree nor Disagree | CC21: Disagree | CD21: Agree | CE21: Disagree | CF21: Disagree | CG21: Neither Agree nor Disagree | CH21: Neither Agree nor Disagree | CI21: Neither Agree nor Disagree | CJ21: =COUNTIF(X21,TRUE)+COUNTIF(AJ21,TRUE)+COUNTIF(AV21,TRUE)+COUNTIF(BH21,TRUE)+COUNTIF(BT21,TRUE) -> 1 | CK21: =(VLOOKUP(BZ21,References!$A$1:$C$6,2)+VLOOKUP(CA21,References!$A$1:$C$6,3)+VLOOKUP(CB21,References!$A$1:$C$6,2)+VLOOKUP(CC21,References!$A$1:$C$6,3)+VLOOKUP(CD21,References!$A$1:$C$6,2)+VLOOKUP(CE21,References!$A$1:$C$6,3)+VLOOKUP(CF21,References!$A$1:$C$6,2)+VLOOKUP(CG21,References!$A$1:$C$6,3)+VLOOKUP(CH21,References!$A$1:$C$6,2)+VLOOKUP(CI21,References!$A$1:$C$6,3))*2.5 -> 50 | CL21: The auto generated json can be useful for complex password policies without having ever dealt with JSON | CM21: I think it's a great library, but maybe the documentation itself could be more descriptive and have more than one example for each case.
A22: 4712 | B22: R21 | C22: =A22/60 -> 78.533333 | D22: =(G22-E22)/60 -> 1.3958833 | E22: 29.314 | F22: 100.574 | G22: 113.067 | H22: 4 | I22: 0.1.9 | J22: Senior | K22: Computer Science | L22: Female | M22: =(P22-N22)/60 -> 6.8628833 | N22: 47.641 | O22: 47.641 | P22: 459.414 | Q22: 1 | R22: =(U22-S22)/60 -> 3.2692833 | S22: 35.579 | T22: 228.022 | U22: 231.736 | V22: 10 | W22: TRUE | X22: TRUE | Y22: Generated | Z22: =AVERAGE(AA22:AC22) -> 7 | AA22: 7 | AB22: 7 | AC22: 7 | AD22: =(AG22-AE22)/60 -> 22.9161 | AE22: 32.147 | AF22: 1403.041 | AG22: 1407.113 | AH22: 12 | AI22: TRUE | AJ22: TRUE | AK22: Generated | AL22: =AVERAGE(AM22:AO22) -> 4 | AM22: 4 | AN22: 4 | AO22: 4 | AP22: =(AS22-AQ22)/60 -> 7.7684333 | AQ22: 54.221 | AR22: 518.016 | AS22: 520.327 | AT22: 11 | AU22: TRUE | AV22: TRUE | AW22: Generated | AX22: =AVERAGE(AY22:BA22) -> 7 | AY22: 7 | AZ22: 7 | BA22: 7 | BB22: =(BE22-BC22)/60 -> 8.8264833 | BC22: 3.36 | BD22: 530.146 | BE22: 532.949 | BF22: 18 | BG22: TRUE | BH22: TRUE | BI22: Generated | BJ22: =AVERAGE(BK22:BM22) -> 6 | BK22: 6 | BL22: 5 | BM22: 7 | BN22: =(BQ22-BO22)/60 -> 11.4995 | BO22: 3.333 | BP22: 691.249 | BQ22: 693.303 | BR22: 12 | BS22: TRUE | BT22: TRUE | BU22: Generated | BV22: =AVERAGE(BW22:BY22) -> 5.3333333 | BW22: 5 | BX22: 5 | BY22: 6 | BZ22: Strongly Agree | CA22: Disagree | CB22: Agree | CC22: Strongly disagree | CD22: Strongly Agree | CE22: Disagree | CF22: Agree | CG22: Strongly disagree | CH22: Agree | CI22: Strongly disagree | CJ22: =COUNTIF(X22,TRUE)+COUNTIF(AJ22,TRUE)+COUNTIF(AV22,TRUE)+COUNTIF(BH22,TRUE)+COUNTIF(BT22,TRUE) -> 5 | CK22: =(VLOOKUP(BZ22,References!$A$1:$C$6,2)+VLOOKUP(CA22,References!$A$1:$C$6,3)+VLOOKUP(CB22,References!$A$1:$C$6,2)+VLOOKUP(CC22,References!$A$1:$C$6,3)+VLOOKUP(CD22,References!$A$1:$C$6,2)+VLOOKUP(CE22,References!$A$1:$C$6,3)+VLOOKUP(CF22,References!$A$1:$C$6,2)+VLOOKUP(CG22,References!$A$1:$C$6,3)+VLOOKUP(CH22,References!$A$1:$C$6,2)+VLOOKUP(CI22,References!$A$1:$C$6,3))*2.5 -> 72.5 | CL22: The library is well-written, and straight-forward. The examples help a lot. Syntax actually makes sense, which I am grateful for. | CM22: I was confused at first on the different features of a password, like the requirements for setting charsets and rules vs the actual PCPRule where things like prohibited_substrings can be specified. Having a small section explaining the difference of these could help. After I understood this, there wasn't many problems I encountered. | CN22: N/A
A23: 2339 | B23: R22 | C23: =A23/60 -> 38.983333 | D23: =(G23-E23)/60 -> 1.9814833 | E23: 62.467 | F23: 173.669 | G23: 181.356 | H23: 10 | I23: 0.1.9 | J23: MS student | K23: Computer Science | L23: Male | M23: =(P23-N23)/60 -> 0.36281667 | N23: 41.155 | O23: 41.155 | P23: 62.924 | Q23: 1 | R23: =(U23-S23)/60 -> 0.75688333 | S23: 57.881 | T23: 101.683 | U23: 103.294 | V23: 8 | W23: TRUE | X23: TRUE | Y23: Generated | Z23: =AVERAGE(AA23:AC23) -> 6.3333333 | AA23: 7 | AB23: 5 | AC23: 7 | AD23: =(AG23-AE23)/60 -> 3.39125 | AE23: 27.452 | AF23: 228.118 | AG23: 230.927 | AH23: 3 | AI23: TRUE | AJ23: TRUE | AK23: Generated | AL23: =AVERAGE(AM23:AO23) -> 7 | AM23: 7 | AN23: 7 | AO23: 7 | AP23: =(AS23-AQ23)/60 -> 3.1537333 | AQ23: 157.964 | AR23: 345.488 | AS23: 347.188 | AT23: 4 | AU23: TRUE | AV23: TRUE | AW23: Generated | AX23: =AVERAGE(AY23:BA23) -> 6 | AY23: 6 | AZ23: 6 | BA23: 6 | BB23: =(BE23-BC23)/60 -> 1.7829333 | BC23: 85.895 | BD23: 191.639 | BE23: 192.871 | BF23: 7 | BG23: TRUE | BH23: TRUE | BI23: Generated | BJ23: =AVERAGE(BK23:BM23) -> 7 | BK23: 7 | BL23: 7 | BM23: 7 | BN23: =(BQ23-BO23)/60 -> 13.071383 | BO23: 7.946 | BP23: 788.057 | BQ23: 792.229 | BR23: 9 | BS23: TRUE | BT23: FALSE | BU23: Generated | BV23: =AVERAGE(BW23:BY23) -> 6.3333333 | BW23: 6 | BX23: 6 | BY23: 7 | BZ23: Agree | CA23: Disagree | CB23: Disagree | CC23: Neither Agree nor Disagree | CD23: Agree | CE23: Disagree | CF23: Neither Agree nor Disagree | CG23: Disagree | CH23: Agree | CI23: Disagree | CJ23: =COUNTIF(X23,TRUE)+COUNTIF(AJ23,TRUE)+COUNTIF(AV23,TRUE)+COUNTIF(BH23,TRUE)+COUNTIF(BT23,TRUE) -> 4 | CK23: =(VLOOKUP(BZ23,References!$A$1:$C$6,2)+VLOOKUP(CA23,References!$A$1:$C$6,3)+VLOOKUP(CB23,References!$A$1:$C$6,2)+VLOOKUP(CC23,References!$A$1:$C$6,3)+VLOOKUP(CD23,References!$A$1:$C$6,2)+VLOOKUP(CE23,References!$A$1:$C$6,3)+VLOOKUP(CF23,References!$A$1:$C$6,2)+VLOOKUP(CG23,References!$A$1:$C$6,3)+VLOOKUP(CH23,References!$A$1:$C$6,2)+VLOOKUP(CI23,References!$A$1:$C$6,3))*2.5 -> 65 | CL23: It's easy to use and well documented | CM23: I didn't get why we needed two sets of charsets | CN23: I guess not
A24: 284480 | B24: R23 | C24: =A24/60 -> 4741.3333 | D24: =(G24-E24)/60 -> 3.7376333 | E24: 40.673 | F24: 260.204 | G24: 264.931 | H24: 6 | I24: 0.1.9 | J24: Senior | K24: Computer Science | L24: Male | M24: =(P24-N24)/60 -> 0.71181667 | N24: 12.121 | O24: 12.121 | P24: 54.83 | Q24: 1 | R24: =(U24-S24)/60 -> 0.52196667 | S24: 278.779 | T24: 307.038 | U24: 310.097 | V24: 3 | W24: TRUE | X24: TRUE | Y24: Generated | Z24: =AVERAGE(AA24:AC24) -> 7 | AA24: 7 | AB24: 7 | AC24: 7 | AD24: =(AG24-AE24)/60 -> 0.070933333 | AE24: 149.138 | AF24: 149.138 | AG24: 153.394 | AH24: 1 | AI24: TRUE | AJ24: TRUE | AK24: Generated | AL24: =AVERAGE(AM24:AO24) -> 7 | AM24: 7 | AN24: 7 | AO24: 7 | AP24: =(AS24-AQ24)/60 -> 5.6818833 | AQ24: 24.452 | AR24: 363.211 | AS24: 365.365 | AT24: 4 | AU24: TRUE | AV24: TRUE | AW24: Generated | AX24: =AVERAGE(AY24:BA24) -> 5.6666667 | AY24: 5 | AZ24: 6 | BA24: 6 | BB24: =(BE24-BC24)/60 -> 0.025766667 | BC24: 60.454 | BD24: 60.454 | BE24: 62 | BF24: 1 | BG24: TRUE | BH24: TRUE | BI24: Generated | BJ24: =AVERAGE(BK24:BM24) -> 7 | BK24: 7 | BL24: 7 | BM24: 7 | BN24: =(BQ24-BO24)/60 -> 18.879 | BO24: 8.092 | BP24: 1139.822 | BQ24: 1140.832 | BR24: 26 | BS24: TRUE | BT24: FALSE | BU24: Manual | BV24: =AVERAGE(BW24:BY24) -> 2 | BW24: 1 | BX24: 1 | BY24: 4 | BZ24: Disagree | CA24: Disagree | CB24: Agree | CC24: Disagree | CD24: Neither Agree nor Disagree | CE24: Agree | CF24: Disagree | CG24: Neither Agree nor Disagree | CH24: Neither Agree nor Disagree | CI24: Disagree | CJ24: =COUNTIF(X24,TRUE)+COUNTIF(AJ24,TRUE)+COUNTIF(AV24,TRUE)+COUNTIF(BH24,TRUE)+COUNTIF(BT24,TRUE) -> 4 | CK24: =(VLOOKUP(BZ24,References!$A$1:$C$6,2)+VLOOKUP(CA24,References!$A$1:$C$6,3)+VLOOKUP(CB24,References!$A$1:$C$6,2)+VLOOKUP(CC24,References!$A$1:$C$6,3)+VLOOKUP(CD24,References!$A$1:$C$6,2)+VLOOKUP(CE24,References!$A$1:$C$6,3)+VLOOKUP(CF24,References!$A$1:$C$6,2)+VLOOKUP(CG24,References!$A$1:$C$6,3)+VLOOKUP(CH24,References!$A$1:$C$6,2)+VLOOKUP(CI24,References!$A$1:$C$6,3))*2.5 -> 50 | CL24: The support documents were much appreciated. | CM24: It seemed to be a bit inconsistent with how character requirements worked. In particular, I had trouble doing "require = ['upper', 'lower']" as a PCPRule, and the inability to use 'upper' and 'lower' for charset_requirements seemed odd to me (see note in feedback). | CN24: It seemed like for the last question (where you were meant to make the charset_requirements specify a requirement of 1 lower, 1 upper, and 2 symbols) did not work correctly, as I got the error: ValueError: rules[0].charset_requirements[lower] is not a valid charset. Valid charset are {'symbols', 'digits', 'alphabet'}. I am not entirely sure if this is an oversight, but if it is not, it did feel a bit unintuitive.
A25: 3608 | B25: R24 | C25: =A25/60 -> 60.133333 | D25: =(G25-E25)/60 -> 1.1260833 | E25: 130.573 | F25: 195.958 | G25: 198.138 | H25: 9 | I25: 0.1.9 | J25: MS student | K25: Computer Science | L25: Male | M25: =(P25-N25)/60 -> 0.30748333 | N25: 37.175 | O25: 37.175 | P25: 55.624 | Q25: 1 | R25: =(U25-S25)/60 -> 14.270883 | S25: 26.945 | T25: 876.998 | U25: 883.198 | V25: 2 | W25: TRUE | X25: TRUE | Y25: Generated | Z25: =AVERAGE(AA25:AC25) -> 7 | AA25: 7 | AB25: 7 | AC25: 7 | AD25: =(AG25-AE25)/60 -> 5.50685 | AE25: 8.622 | AF25: 331.303 | AG25: 339.033 | AH25: 2 | AI25: TRUE | AJ25: TRUE | AK25: Generated | AL25: =AVERAGE(AM25:AO25) -> 7 | AM25: 7 | AN25: 7 | AO25: 7 | AP25: =(AS25-AQ25)/60 -> 9.4785667 | AQ25: 59.588 | AR25: 623.747 | AS25: 628.302 | AT25: 3 | AU25: TRUE | AV25: TRUE | AW25: Generated | AX25: =AVERAGE(AY25:BA25) -> 7 | AY25: 7 | AZ25: 7 | BA25: 7 | BB25: =(BE25-BC25)/60 -> 0.0416 | BC25: 99.931 | BD25: 99.931 | BE25: 102.427 | BF25: 1 | BG25: TRUE | BH25: TRUE | BI25: Generated | BJ25: =AVERAGE(BK25:BM25) -> 7 | BK25: 7 | BL25: 7 | BM25: 7 | BN25: =(BQ25-BO25)/60 -> 16.552883 | BO25: 30.485 | BP25: 937.181 | BQ25: 1023.658 | BR25: 13 | BS25: TRUE | BT25: TRUE | BU25: Generated | BV25: =AVERAGE(BW25:BY25) -> 6.6666667 | BW25: 7 | BX25: 6 | BY25: 7 | BZ25: Agree | CA25: Disagree | CB25: Agree | CC25: Disagree | CD25: Agree | CE25: Disagree | CF25: Agree | CG25: Disagree | CH25: Agree | CI25: Disagree | CJ25: =COUNTIF(X25,TRUE)+COUNTIF(AJ25,TRUE)+COUNTIF(AV25,TRUE)+COUNTIF(BH25,TRUE)+COUNTIF(BT25,TRUE) -> 5 | CK25: =(VLOOKUP(BZ25,References!$A$1:$C$6,2)+VLOOKUP(CA25,References!$A$1:$C$6,3)+VLOOKUP(CB25,References!$A$1:$C$6,2)+VLOOKUP(CC25,References!$A$1:$C$6,3)+VLOOKUP(CD25,References!$A$1:$C$6,2)+VLOOKUP(CE25,References!$A$1:$C$6,3)+VLOOKUP(CF25,References!$A$1:$C$6,2)+VLOOKUP(CG25,References!$A$1:$C$6,3)+VLOOKUP(CH25,References!$A$1:$C$6,2)+VLOOKUP(CI25,References!$A$1:$C$6,3))*2.5 -> 75 | CL25: The ease to use the password policy creation | CM25: Documentation could be more organized
A26: 5369 | B26: R25 | C26: =A26/60 -> 89.483333 | D26: =(G26-E26)/60 -> 0.60595 | E26: 11.479 | F26: 46.597 | G26: 47.836 | H26: 6 | I26: 0.1.9 | J26: Junior | K26: Computer Science | L26: Male | M26: =(P26-N26)/60 -> 0.4725 | N26: 11.951 | O26: 11.951 | P26: 40.301 | Q26: 1 | R26: =(U26-S26)/60 -> 2.8841833 | S26: 42.823 | T26: 206.6 | U26: 215.874 | V26: 17 | W26: TRUE | X26: TRUE | Y26: Generated | Z26: =AVERAGE(AA26:AC26) -> 7 | AA26: 7 | AB26: 7 | AC26: 7 | AD26: =(AG26-AE26)/60 -> 0.30163333 | AE26: 86.722 | AF26: 101.986 | AG26: 104.82 | AH26: 2 | AI26: TRUE | AJ26: TRUE | AK26: Generated | AL26: =AVERAGE(AM26:AO26) -> 7 | AM26: 7 | AN26: 7 | AO26: 7 | AP26: =(AS26-AQ26)/60 -> 0.0413 | AQ26: 273.278 | AR26: 273.278 | AS26: 275.756 | AT26: 1 | AU26: TRUE | AV26: TRUE | AW26: Generated | AX26: =AVERAGE(AY26:BA26) -> 7 | AY26: 7 | AZ26: 7 | BA26: 7 | BB26: =(BE26-BC26)/60 -> 0.03505 | BC26: 115.273 | BD26: 115.273 | BE26: 117.376 | BF26: 1 | BG26: TRUE | BH26: TRUE | BI26: Generated | BJ26: =AVERAGE(BK26:BM26) -> 7 | BK26: 7 | BL26: 7 | BM26: 7 | BN26: =(BQ26-BO26)/60 -> 50.304667 | BO26: 460.364 | BP26: 3476.022 | BQ26: 3478.644 | BR26: 10 | BS26: TRUE | BT26: TRUE | BU26: Generated | BV26: =AVERAGE(BW26:BY26) -> 3 | BW26: 3 | BX26: 3 | BY26: 3 | BZ26: Neither Agree nor Disagree | CA26: Agree | CB26: Neither Agree nor Disagree | CC26: Disagree | CD26: Disagree | CE26: Agree | CF26: Neither Agree nor Disagree | CG26: Neither Agree nor Disagree | CH26: Neither Agree nor Disagree | CI26: Disagree | CJ26: =COUNTIF(X26,TRUE)+COUNTIF(AJ26,TRUE)+COUNTIF(AV26,TRUE)+COUNTIF(BH26,TRUE)+COUNTIF(BT26,TRUE) -> 5 | CK26: =(VLOOKUP(BZ26,References!$A$1:$C$6,2)+VLOOKUP(CA26,References!$A$1:$C$6,3)+VLOOKUP(CB26,References!$A$1:$C$6,2)+VLOOKUP(CC26,References!$A$1:$C$6,3)+VLOOKUP(CD26,References!$A$1:$C$6,2)+VLOOKUP(CE26,References!$A$1:$C$6,3)+VLOOKUP(CF26,References!$A$1:$C$6,2)+VLOOKUP(CG26,References!$A$1:$C$6,3)+VLOOKUP(CH26,References!$A$1:$C$6,2)+VLOOKUP(CI26,References!$A$1:$C$6,3))*2.5 -> 40 | CL26: I like that there is not an extreme amount of complexity as far as available options and functions. | CM26: It seemed like the different functions and classes don't mesh together very well. | CN26: I don't understand the purpose of SimplePCP(). I feel like the password library should be easy enough to use already that it's not necessary to provide an even simpler version with different configuration options. It makes it hard to upgrade later to a more complex system. The PCP() class isn't very hard to write so I don't think SimplePCP() is necessary- it just confused me. Some things were not intuitive. For example, you can't use `required` inside a PCPRule(), which doesn't make sense.
